<?xml version="1.0" ?>
<!-- Generated using onshape-to-robot -->
<!-- Onshape https://cad.onshape.com/documents/fb40679e5085125a52f9d8c2/w/bc70b1a5b80ef34e9536dda2/e/ebd50f61e064fd684c29d65c -->
<mujoco model="wheel_milli_quad">
  <compiler angle="radian" meshdir="assets" autolimits="true"/>
  <default>
    <default class="wheel_milli_quad">
      <!-- <joint frictionloss="2e-7"/> -->
      <default class="magnet">
        <geom mass="9e-6" type="mesh" mesh="magnet" material="magnet_material"/>
      </default>
      <default class="leg">
        <geom mass="5e-7" type="mesh" mesh="part_1" material="part_1_material"/>
      </default>
      <default class="leg_box">
        <geom mass="3e-6" type="mesh" mesh="part_1" material="part_1_material"/>
      </default>
      <default class="body">
        <geom mass="5.3e-5" type="mesh" mesh="body" material="body_material"/>
      </default>
    </default>
  </default>
  <worldbody>
    <!-- Link body -->
    <body name="body" pos="0 0 0" quat="1 0 0 0" childclass="wheel_milli_quad">
      <freejoint name="body_freejoint"/>
      <geom class="body" pos="0 0 -0.00268252" quat="0 0 1 0"/>  <!-- FLIPPED 180° around Y-axis (roll) + Z offset -->
      <!-- Link part_1 -->
      <body name="part_1" pos="0.00342 -0.00298 -0.00134126" quat="0.707107 -0.707107 0 0">
        <!-- Joint from body to part_1 -->
        <joint axis="0 0 1" name="FR" type="hinge"/>
        <geom class="leg" pos="-4.51028e-17 3.31766e-17 0.0605017" quat="0.707107 -0.707107 0 0"/>
        <geom class="magnet" pos="8.23994e-18 2.1684e-18 -0.00074" quat="0.707107 0.707107 -0 -0"/>
        
      </body>
      <!-- Link part_1_2 -->
      <body name="part_1_2" pos="0.00342 0.00298 -0.00134126" quat="0 0 0.707107 0.707107">
        <!-- Joint from body to part_1_2 -->
        <joint axis="0 0 1" name="FL" type="hinge"/>
        <geom class="leg" pos="4.51028e-17 3.31766e-17 -0.0605017" quat="0 0 0.707107 0.707107"/>
        <geom class="magnet" pos="-8.23994e-18 2.1684e-18 0.00074" quat="3.83323e-17 -0 0.707107 0.707107"/>
        
      </body>
      <!-- Link part_1_3 -->
      <body name="part_1_3" pos="-0.00342 -0.00318 -0.00134126" quat="0.707107 -0.707107 0 0">
        <!-- Joint from body to part_1_3 -->
        <joint axis="0 0 1" name="BR" type="hinge"/>
        <geom class="magnet" pos="8.23994e-18 1.30104e-18 -0.00054" quat="0.707107 -0.707107 -0 -3.83323e-17"/>
        <geom class="leg" pos="-4.51028e-17 3.31766e-17 0.0607017" quat="0.707107 -0.707107 0 0"/>
        
      </body>
      <!-- Link part_1_4 -->
      <body name="part_1_4" pos="-0.00342 0.00298 -0.00134126" quat="0 0 -0.707107 0.707107">
        <!-- Joint from body to part_1_4 -->
        <joint axis="0 0 1" name="BL" type="hinge"/>
        <geom class="leg" pos="4.46691e-17 -3.31766e-17 0.0605017" quat="0 0 -0.707107 0.707107"/>
        <geom class="magnet" pos="-8.67362e-18 -2.1684e-18 -0.00074" quat="3.83323e-17 -0 0.707107 0.707107"/>
        
      </body>
    </body>
  </worldbody>
  <asset>
    <mesh file="body.stl"/>
    <mesh file="part_1.stl"/>
    <mesh file="magnet.stl"/>
    <material name="body_material" rgba="0.796078 0.823529 0.937255 1"/>
    <material name="part_1_material" rgba="0.796078 0.823529 0.937255 1"/>
    <material name="magnet_material" rgba="0.615686 0.811765 0.929412 1"/>
  </asset>
</mujoco>
